Workbook
Name ____________________a65537: #REF!
Name ____________________a65537: #REF!
Name ____________________A65555: #REF!
Name ____________________A65555: #REF!
Name ____________________A65658: #REF!
Name ____________________A65658: #REF!
Name ___________________a65537: #REF!
Name ___________________a65537: #REF!
Name ___________________A65555: #REF!
Name ___________________A65555: #REF!
Name ___________________A65658: #REF!
Name ___________________A65658: #REF!
Name __________________a65537: #REF!
Name __________________a65537: #REF!
Name __________________A65555: #REF!
Name __________________A65555: #REF!
Name __________________A65658: #REF!
Name __________________A65658: #REF!
Name __________________bol1: #REF!
Name __________________bol1: #REF!
Name __________________lb1: #REF!
Name __________________lb1: #REF!
Name __________________lb2: #REF!
Name __________________lb2: #REF!
Name __________________mm1: #REF!
Name __________________mm1: #REF!
Name __________________mm2: #REF!
Name __________________mm2: #REF!
Name __________________mm3: #REF!
Name __________________mm3: #REF!
Name _________________a65537: #REF!
Name _________________a65537: #REF!
Name _________________A65555: #REF!
Name _________________A65555: #REF!
Name _________________A65658: #REF!
Name _________________A65658: #REF!
Name _________________bol1: #REF!
Name _________________bol1: #REF!
Name _________________lb1: #REF!
Name _________________lb1: #REF!
Name _________________lb2: #REF!
Name _________________lb2: #REF!
Name _________________mm1: #REF!
Name _________________mm1: #REF!
Name _________________mm2: #REF!
Name _________________mm2: #REF!
Name _________________mm3: #REF!
Name _________________mm3: #REF!
Name ________________a65537: #REF!
Name ________________a65537: #REF!
Name ________________A65555: #REF!
Name ________________A65555: #REF!
Name ________________A65658: #REF!
Name ________________A65658: #REF!
Name ________________bol1: #REF!
Name ________________bol1: #REF!
Name ________________lb1: #REF!
Name ________________lb1: #REF!
Name ________________lb2: #REF!
Name ________________lb2: #REF!

Sheet Misk Format
A1: Mawallah Site BOQ
A2: SL.NO | B2: DESCRIPTION | C2: UNIT | D2: QUANTITY | E2: UNIT RATE | F2: AMOUNT | G2: VAT 5% | H2: TOTAL AMOUNT | I2: LPO/ CONTRACT | J2: ACTUAL | K2: BALANCE TO PAY | L2: REMARKS
B3: CIVIL WORKS
A4: A | B4: Structural Works
A5: 1 | B5: Survey & Tasleem Align Marking | C5: Ls | D5: 1 | E5: 20 | F5: =(D5*E5) -> 20 | H5: =SUM(F5+G5) -> 20
A6: 2 | B6: Sub Contractor for the structure works | C6: Ls | D6: 1 | E6: 40102 | F6: =(D6*E6) -> 40102 | H6: =SUM(F6+G6) -> 40102
A7: 3 | B7: Sub Contractor for the MEP works | C7: Sqm | D7: 2721.6 | E7: 3.8 | F7: =(D7*E7) -> 10342.08 | H7: =SUM(F7+G7) -> 10342.08
A8: 4 | B8: Measuring Tape 5m | C8: Nos | D8: 2 | E8: 0.8 | F8: =(D8*E8) -> 1.6 | G8: =(F8*5%) -> 0.08 | H8: =SUM(F8+G8) -> 1.68
A9: 5 | B9: Excavation Contract | C9: Ls | D9: 1 | E9: 1400 | F9: =(D9*E9) -> 1400 | H9: =SUM(F9+G9) -> 1400
A10: 6 | B10: Backfilling equipment contract | C10: Days | D10: 5 | E10: 60 | F10: =(D10*E10) -> 300 | H10: =SUM(F10+G10) -> 300
A11: 7 | B11: ATT | C11: Sqm | D11: 450 | E11: 0.265 | F11: =(D11*E11) -> 119.25 | G11: =(F11*5%) -> 5.9625 | H11: =SUM(F11+G11) -> 125.2125
A12: 8 | B12: Polythene sheet PCC Bottom + Grade slab Bottom + Concrete protection | C12: Roll | D12: 35 | E12: 5 | F12: =(D12*E12) -> 175 | G12: =(F12*5%) -> 8.75 | H12: =SUM(F12+G12) -> 183.75
A13: 9 | B13: PCC C15 | C13: m3 | D13: 48 | E13: 17 | F13: =(D13*E13) -> 816 | G13: =(F13*5%) -> 40.8 | H13: =SUM(F13+G13) -> 856.8
A14: 10 | B14: SRC - C40 | C14: m3 | D14: 544 | E14: 22 | F14: =(D14*E14) -> 11968 | G14: =(F14*5%) -> 598.4 | H14: =SUM(F14+G14) -> 12566.4
A15: 11 | B15: OPC -C40 | C15: m3 | D15: 1082 | E15: 22 | F15: =(D15*E15) -> 23804 | G15: =(F15*5%) -> 1190.2 | H15: =SUM(F15+G15) -> 24994.2
A16: 12 | B16: SRC-C30 for the grade slab | C16: m3 | D16: 42 | E16: 18 | F16: =(D16*E16) -> 756 | G16: =(F16*5%) -> 37.8 | H16: =SUM(F16+G16) -> 793.8
A17: 13 | B17: A-193- Mesh | C17: Nos | D17: 30 | E17: 6.6 | F17: =(D17*E17) -> 198 | G17: =(F17*5%) -> 9.9 | H17: =SUM(F17+G17) -> 207.9
A18: 14 | B18: Reinforcement | C18: Ton | D18: 226.5 | E18: 287 | F18: =+D18*E18 -> 65005.5 | G18: =(F18*5%) -> 3250.275 | H18: =SUM(F18+G18) -> 68255.775
A19: 15 | B19: Binding Wire | C19: KG | D19: 1200 | E19: 0.6 | F19: =(D19*E19) -> 720 | G19: =(F19*5%) -> 36 | H19: =SUM(F19+G19) -> 756
A20: 16 | B20: Site Set up | C20: Ls | D20: 1 | E20: 1500 | F20: =(D20*E20) -> 1500 | H20: =SUM(F20+G20) -> 1500
A21: 17 | B21: Cement for the substructure works | C21: Bag | D21: 50 | E21: 1.53 | F21: =(D21*E21) -> 76.5 | G21: =(F21*5%) -> 3.825 | H21: =SUM(F21+G21) -> 80.325
A22: 18 | B22: Wash Sand | C22: Trip | D22: 1 | E22: 70 | F22: =(D22*E22) -> 70 | G22: =(F22*5%) -> 3.5 | H22: =SUM(F22+G22) -> 73.5
A23: 19 | B23: Bitumen Paint | C23: Drum | D23: 4 | E23: 45 | F23: =(D23*E23) -> 180 | G23: =(F23*5%) -> 9 | H23: =SUM(F23+G23) -> 189
A25: B | B25: Shuttering Materials | H25: =SUM(F25+G25) -> 0
A26: 1 | B26: Plywood 18mm | C26: Nos | D26: 350 | E26: 6 | F26: =(D26*E26) -> 2100 | G26: =(F26*5%) -> 105 | H26: =SUM(F26+G26) -> 2205
A27: 2 | B27: White Wood 1"4" | C27: Nos | D27: 180 | E27: 1.45 | F27: =(D27*E27) -> 261 | G27: =(F27*5%) -> 13.05 | H27: =SUM(F27+G27) -> 274.05
A28: 3 | B28: White Wood 2"*3" | C28: Nos | D28: 1350 | E28: 1.7 | F28: =(D28*E28) -> 2295 | G28: =(F28*5%) -> 114.75 | H28: =SUM(F28+G28) -> 2409.75
A29: 5 | B29: Doka System for the scaffolding | C29: Month | D29: 8 | E29: 750 | F29: =(D29*E29) -> 6000 | G29: =(F29*5%) -> 300 | H29: =SUM(F29+G29) -> 6300
A30: 6 | B30: Nail | C30: Ls | D30: 1 | E30: 800 | F30: =(D30*E30) -> 800 | G30: =(F30*5%) -> 40 | H30: =SUM(F30+G30) -> 840
A31: 7 | B31: Shuttering Tape | C31: Qtn | D31: 25 | E31: 3 | F31: =(D31*E31) -> 75 | G31: =(F31*5%) -> 3.75 | H31: =SUM(F31+G31) -> 78.75
A32: 8 | B32: C-Clamp | C32: Nos | D32: 300 | E32: 0.7 | F32: =(D32*E32) -> 210 | G32: =(F32*5%) -> 10.5 | H32: =SUM(F32+G32) -> 220.5
A33: 9 | B33: Tie Rod | C33: Ls | D33: 800 | E33: 1 | F33: =(D33*E33) -> 800 | G33: =(F33*5%) -> 40 | H33: =SUM(F33+G33) -> 840
A34: 10 | B34: 25mm Conduit Pipe | C34: Nos | D34: 350 | E34: 0.4 | F34: =(D34*E34) -> 140 | G34: =(F34*5%) -> 7 | H34: =SUM(F34+G34) -> 147
A36: C | B36: Block Works
A37: 1 | B37: 100 mm thick Bottom Closed Blockes | C37: Nos | D37: 10000 | E37: 0.15 | F37: =(D37*E37) -> 1500 | G37: =(F37*5%) -> 75 | H37: =SUM(F37+G37) -> 1575
A38: 2 | B38: 200mm thick bottom Closed Blocks | C38: Nos | D38: 63000 | E38: 0.16 | F38: =(D38*E38) -> 10080 | G38: =(F38*5%) -> 504 | H38: =SUM(F38+G38) -> 10584
A39: 3 | B39: Tower Hoist Diesl engine lift | C39: Nos | D39: 1 | E39: 2750 | F39: =(D39*E39) -> 2750 | G39: =(F39*5%) -> 137.5 | H39: =SUM(F39+G39) -> 2887.5
A40: 4 | B40: Hoist Installation | C40: ls | D40: 1 | E40: 200 | F40: =(D40*E40) -> 200 | H40: =SUM(F40+G40) -> 200
A41: 5 | B41: Cement for Block work | C41: Bag | D41: 1500 | E41: 1.37 | F41: =(D41*E41) -> 2055 | G41: =(F41*5%) -> 102.75 | H41: =SUM(F41+G41) -> 2157.75
A42: 6 | B42: Aggregate | C42: Trip | D42: 3 | E42: 50 | F42: =(D42*E42) -> 150 | G42: =(F42*5%) -> 7.5 | H42: =SUM(F42+G42) -> 157.5
...

Sheet GS
A1: CONSTRUCTION OF RESIDENTAL/COMMERCIAL BUILDING @ Alansab Plot 1127
A4: GENERAL SUMMARY
A8: ITEM | B8: ITEM DESCRIPTION | E8: AMOUNT
A9: REF. | E9: ( R.O. )
C13: BILL NO. 1 PRELIMINARIES | E13: 3000
C16: BILL NO. 2 Sub Contractors Price
C17: 1) Structural Subcontractor | E17: 86446.16
C18: 2) MEP Sub Contractors | E18: 20927.55
C20: BILL NO. 3 Main building | E20: =+'C_Bill No. 3 Main bld (2)'!H367 -> 490778.86
C23: BILL NO. 4 Ancillary Structures | E23: ='Bill No. 4 Ancillary'!H35 -> 2901.7897
C25: BILL NO. 5 Electrical & ELV | E25: =+'Bill No.5 Electrical & ELV'!H592 -> 77653.48
C27: BILL NO. 6 Plumbing Work | E27: =+'Bill No.6 Plumbing'!H212 -> 43662.305
C30: BILL NO. 7 Finishing Work Packages | E30: =+'BILL NO.9 PROVISIONAL'!H38 -> 152700
C37: TOTAL AMOUNT (RO.) | E37: =SUM(E13:E35) -> 878070.15
C42: TOTAL CARRIED TO LITTER OF TENDER
E43: =E37+E39 -> 878070.15
C45: Total Area of the Building | E45: 5979.3
C46: Rate for the building (Rial/Sqm) | E46: =E43/E45 -> 146.85166
E51: =+E42*0.05 -> 0

Sheet C_Bill No. 3 Main bld (2)
A2: BILL NO. 3 - CIVIL WORKS
A4: ITEM | B4: ITEM DESCRIPTION | E4: QTY. | F4: UNIT | G4: RATE | H4: AMOUNT | K4: Calculated Qty
A5: REF. | H5: ( R.O. )
C7: CIVIL WORKS
C9: SUBSTRUCTURE
C11: Note:- Substructure Quantities are measured up to Ground Floor level except Finishes
C13: Excavation
A15: A | C15: Site preparation, removing 200mm depth top soil, clearing shrubs including cart away etc. | E15: =K15 -> 752.103 | F15: m2 | G15: 0 | H15: =+G15*E15 -> 0 | K15: =M.S!F8*M.S!G8 -> 752.103
M16: =4100/5227 -> 0.78438875
A17: B | C17: Excavation to reduce level including to receive pits for the foundations | E17: =K17 -> 5227.1159 | F17: m3 | G17: 0.78439 | H17: =(G17*E17) -> 4100.0974 | I17: 1900+400+1800 | K17: =M.S!I10 -> 5227.1159
A19: C | C19: Extra over for excavating in rock | E19: =K19 -> 0 | F19: m3 | H19: =+G19*E19 -> 0 | K19: 0
C21: Filling and Removals
A23: D | C23: Fill excavations and under floors & Outside with graded and hard imported granular material in layers not exceeding 150mm high and compacting the soil to obtain a density of 98% of the maximum dry density including watering and compaction tests to the approval of the Engineer | E23: 1400 | F23: m3 | G23: 2 | H23: =(G23*E23) -> 2800 | K23: 0
A25: E | C25: Spreading suitable excavated material over the site and compaction in layers not exceeding 150mm high and compacting the soil to obtain a density of 98% of the maximum dry density including watering and compaction tests to the approval of the Engineer | E25: =K25 -> 0 | F25: m3 | K25: 0
A27: F | C27: Remove unsuitable excavated material and cart away to Municipal approved dumping yard | E27: =K27 -> 5227.1159 | F27: m3 | H27: 500 | K27: =M.S!I10 -> 5227.1159
C28: To Collection | G28: R.O.
H29: =SUM(H15:H28) -> 7400.0974
C31: Substructure (Cont'd)
C33: Anti-termite barrier
P34: =+E75+E130+'Bill No. 4 Ancillary'!E20 -> 492873.14
A35: A | C35: Anti-termite treatment applied to surface of filling under floors including peripheral area with approved chemicals with 10-years guarantee as specified and to the approval of the Engineer (measured flat over plinth area) | E35: 1500 | F35: m2 | G35: 0.265 | H35: =+G35*E35 -> 397.5 | K35: =M.S!F8*M.S!G8 -> 752.103
C37: Concrete Work
C39: SRC plain poured pre-mixed concrete, Grade 15N/mm² including placing, curing, cube tests and form work as required.
A41: B | C41: Blinding Concrete | E41: =K41 -> 165.3649 | F41: m3 | G41: 17.5 | H41: =+G41*E41 -> 2893.8857 | K41: =M.S!R27+M.S!S27 -> 165.3649
C43: SRC reinforced pre-mixed cement concrete, Grade 40N/mm² as specified including placing, vibrating, curing and cube tests, etc.,
A45: C | C45: Raft, Shore pile, Capping beam | E45: =K45 -> 670.7941 | F45: m3 | G45: 19.75 | H45: =+G45*E45 -> 13248.183 | K45: =M.S!V31+M.S!H291+M.S!I293 -> 670.7941
A47: D | C47: Columns | E47: =K47 -> 62.115 | F47: m3 | G47: 19.75 | H47: =+G47*E47 -> 1226.7713 | K47: =M.S!V43 -> 62.115
A49: E | C49: RCC Lift wall/Core wall | E49: =K49 -> 35.8566 | F49: m3 | G49: 19.75 | H49: =+G49*E49 -> 708.16785 | K49: =M.S!V89 -> 35.8566
A51: F | C51: Shear Wall | E51: =+K51 -> 192.8043 | F51: m3 | G51: 19.75 | H51: =+G51*E51 -> 3807.8849 | K51: =M.S!V109 -> 192.8043
C52: To Collection | G52: R.O.
H53: =SUM(H35:H52) -> 22282.393
C55: Substructure (Cont'd)
C57: Formwork
A59: A | C59: Foundations | E59: =K59 -> 88.848 | F59: m2 | G59: 2 | H59: =+G59*E59 -> 177.696 | K59: =M.S!X31 -> 88.848
A61: B | C61: Columns | E61: =K61 -> 62.115 | F61: m2 | G61: 2 | H61: =+G61*E61 -> 124.23 | K61: =M.S!V43 -> 62.115
A63: C | C63: RCC Lift wall/Core wall | E63: =K63 -> 1664.208 | F63: m2 | G63: 2 | H63: =+G63*E63 -> 3328.416 | K63: =M.S!X89+M.S!X109 -> 1664.208
A65: D | C65: Plinth Beams | E65: =K65 -> 10.5522 | F65: m2 | G65: 2 | H65: =+G65*E65 -> 21.1044 | K65: =M.S!V127 -> 10.5522
A67: E | C67: Ramp | E67: =K67 -> 5 | F67: m2 | G67: 2 | H67: =+G67*E67 -> 10 | K67: 5
A69: F | C69: Shear Wall | E69: =+K69 -> 3156.392 | F69: m3 | G69: 2 | H69: =+G69*E69 -> 6312.784 | K69: =M.S!X100+M.S!X109 -> 3156.392
C71: Reinforcement Works
...

Sheet Finishesh
A1: Project
A2: sub-masonry works
A4: S.No | B4: Description | C4: Unit | D4: No | F4: L | G4: B | H4: D | I4: Remarks | K4: Flooring | P4: Skirting | T4: Wall | V4: Ceiling | X4: Railings | Y4: LW CON FOR SLOPE | Z4: WPM 0.4cm | AA4: Cement Screed 3cm | AB4: EXTRUDED POLYSTYRENE 5cm. | AC4: PROTECTION BOARD 0.2cm. | AD4: SAND AND MORTAR BED 5cm. | AE4: TERRAZZO TILES 30x30x3cm. | AF4: TERRAZZO SKIRTING 30x10x3cm.
B6: internal
A7: 1 | B7: Ground floor | K7: F1 | L7: F2 | M7: F3 | N7: F4 | O7: F5 | P7: S1 | Q7: S2 | R7: S3 | S7: S4 | T7: W1 | U7: W2 | V7: C1 | W7: C2 | AG7: SCHEDULE OF FINISHING
B8: Shop 13 | C8: SQ M | D8: 1 | E8: 1 | F8: =5.47 -> 5.47 | G8: 3.3 | H8: 4.3 | N8: =F8*G8*D8*E8 -> 18.051 | R8: =((F8+G8*2)*0.15)*D8*E8 -> 1.8105 | U8: =(F8+G8*2)*H8*D8*E8 -> 51.901 | V8: =N8 -> 18.051 | AG8: FLOORING
B9: Shop 14 | C9: SQ M | D9: 1 | E9: 1 | F9: 7.1 | G9: 3.885 | H9: 4.3 | N9: =F9*G9*D9*E9 -> 27.5835 | R9: =((F9+G9*2)*0.15)*E9*D9 -> 2.2305 | U9: =(F9+G9*2)*H9*D9*E9 -> 63.941 | V9: =N9 -> 27.5835 | AG9: TYPE | AH9: DESCRIPTION
B10: Shop 15 | C10: SQ M | D10: 1 | E10: 1 | F10: =SQRT(15) -> 3.8729833 | G10: =F10 -> 3.8729833 | H10: 4.3 | N10: =F10*G10*D10*E10 -> 15 | R10: =((F10+G10*2)*0.15)*E10*D10 -> 1.7428425 | U10: =(F10+G10*2)*H10*D10*E10 -> 49.961485 | V10: =N10 -> 15 | AG10: F1 | AH10: 20mm THICK ITALIAN MARBLE STEPS COLOR ,DESIGN & SHAPE TO BE APPROVED
B11: Shop 16 | C11: SQ M | D11: 1 | E11: 1 | F11: =SQRT(14) -> 3.7416574 | G11: =F11 -> 3.7416574 | H11: 4.3 | N11: =F11*G11*D11*E11 -> 14 | R11: =((F11+G11*2)*0.15)*E11*D11 -> 1.6837458 | U11: =(F11+G11*2)*H11*D11*E11 -> 48.26738 | V11: =N11 -> 14 | AG11: F2 | AH11: 300X600X20mm ITALIAN MARBLE TILES COLOR ,DESIGN & SHAPE TO BE APPROVED
B12: Shop 17 | C12: SQ M | D12: 1 | E12: 1 | F12: =SQRT(30.2) -> 5.4954527 | G12: =F12 -> 5.4954527 | H12: 4.3 | N12: =F12*G12*D12*E12 -> 30.2 | R12: =((F12+G12*2)*0.15)*E12*D12 -> 2.4729537 | U12: =(F12+G12*2)*H12*D12*E12 -> 70.891339 | V12: =N12 -> 30.2 | AG12: F3 | AH12: 400X400X20mm PORCELAIN TILES COLOR ,DESIGN & SHAPE TO BE APPROVED
B13: Guard Room | C13: SQ M | D13: 1 | E13: 1 | F13: 2.84 | G13: 2.84 | H13: 4.3 | N13: =F13*G13*D13*E13 -> 8.0656 | R13: =((F13+G13*2)*0.15)*E13*D13 -> 1.278 | U13: =(F13+G13*2)*H13*D13*E13 -> 36.636 | V13: =N13 -> 8.0656 | AG13: F4 | AH13: 200X200X8mm FULLY VITRIFIED NON-SLIPPERY ITALIAN CERAMIC TILES COLOR ,DESIGN & SHAPE TO BE APPROVED
B14: D5 | D14: -1 | E14: 1 | F14: 1 | H14: 2.2 | N14: =F14*G14*D14*E14 -> 0 | R14: =((F14+G14*2)*0.15)*E14*D14 -> -0.15 | U14: =(F14+G14*2)*H14*D14*E14 -> -2.2 | V14: =N14 -> 0 | AG14: F5 | AH14: 300X300X8mm BEST QUALITY TERRAZZO TILES COLOR ,DESIGN & SHAPE TO BE APPROVED
B15: D6 | D15: -1 | E15: 1 | F15: 0.8 | H15: 2.2 | N15: =F15*G15*D15*E15 -> 0 | R15: =((F15+G15*2)*0.15)*E15*D15 -> -0.12 | U15: =(F15+G15*2)*H15*D15*E15 -> -1.76 | V15: =N15 -> 0 | AG15: SKIRTING
B16: D7 | D16: -1 | E16: 1 | F16: 0.8 | H16: 2.2 | N16: =F16*G16*D16*E16 -> 0 | R16: =((F16+G16*2)*0.15)*E16*D16 -> -0.12 | U16: =(F16+G16*2)*H16*D16*E16 -> -1.76 | V16: =N16 -> 0 | AG16: TYPE | AH16: DESCRIPTION
B17: Gents Toilet | C17: SQ M | D17: 1 | E17: 1 | F17: 1 | G17: 2 | H17: 4.3 | O17: =G17*D17*E17*F17 -> 2 | U17: =(F17+G17*2)*H17*D17*E17 -> 21.5 | W17: =O17 -> 2 | AG17: S1 | AH17: 600X100X20mm ITALIAN MARBLE SKIRTING WITH HALF ROUND TOP EDGE COLOR ,DESIGN & SHAPE TO BE APPROVED.
B18: D6 | D18: -1 | E18: 1 | F18: 0.8 | H18: 2.2 | O18: =G18*D18*E18*F18 -> 0 | U18: =(F18+G18*2)*H18*D18*E18 -> -1.76 | W18: =O18 -> 0 | AG18: S2 | AH18: 400X100X20mm HEIGHT PORCELAIN SKIRTING WITH HALF ROUND TOP EDGE
B19: Ladies Toilet | C19: SQ M | D19: 1 | E19: 1 | F19: 1.5 | G19: 2 | H19: 4.3 | O19: =G19*D19*E19*F19 -> 3 | U19: =(F19+G19*2)*H19*D19*E19 -> 23.65 | W19: =O19 -> 3 | AG19: S3 | AH19: 300X100X20mm HEIGHT TERRAZZO SKIRTING WITH HALF ROUND TOP EDGE
B20: D6* | D20: -1 | E20: 1 | F20: 1 | H20: 2.2 | O20: =G20*D20*E20*F20 -> 0 | U20: =(F20+G20*2)*H20*D20*E20 -> -2.2 | W20: =O20 -> 0 | AG20: S4 | AH20: 20mm THICK GRAY NIGHT MARBLE STEPS COLOR ,DESIGN & SHAPE TO BE APPROVED
B21: Electric room | C21: SQ M | D21: 2 | E21: 1 | F21: 3.56 | G21: 3.56 | H21: 4.3 | O21: =G21*D21*E21*F21 -> 25.3472 | S21: =((G21+F21*2)*0.5)*D21*E21 -> 10.68 | U21: =(F21+G21*2)*H21*D21*E21 -> 91.848 | W21: =O21 -> 25.3472 | AG21: WALLS
B22: D10 | D22: -1 | E22: 1 | F22: 0.9 | H22: 2.2 | O22: =G22*D22*E22*F22 -> 0 | U22: =(F22+G22*2)*H22*D22*E22 -> -1.98 | W22: =O22 -> 0 | AG22: TYPE | AH22: DESCRIPTION
B23: staircse front lobby | C23: SQ M | D23: 1 | E23: 1 | F23: 2.2 | G23: 4.6 | H23: 4.3 | L23: =PRODUCT(D23:G23) -> 10.12 | Q23: =(F23*2+G23*2)*0.15*D23*E23 -> 2.04 | U23: =(F23+G23*2)*H23*D23*E23 -> 49.02 | W23: =L23 -> 10.12 | AG23: W1 | AH23: 1 COAT PRIMER +2 COATS OF PUTTY + 3 COATS OF FENOMASTIC GOLD PAINT OR EQUIVALENT (COLOR SHALL BE FROM M.LN COLOR CHART AS APPROVED BY ENGINEER) ON 20mm THICK CEMENT SAND PLASTER
B24: D10 | D24: -1 | E24: 1 | F24: 0.9 | H24: 2.2 | L24: =F22*G22*D22*E22 -> 0 | Q24: =((F16+G16*2)*0.15)*E16*D16 -> -0.12 | U24: =(F24+G24*2)*H24*D24*E24 -> -1.98 | W24: =L24 -> 0 | AG24: W2 | AH24: 200X300mm GLAZED ITALIAN CERAMIC TILES FOR WALLS UP TO CEILING LEVEL COLOR & DESIGN TO BE APPROVED
B25: Shop 1 | C25: SQ M | D25: 1 | E25: 1 | F25: 3 | G25: 10.45 | H25: 4.3 | N25: =F25*G25*D25*E25 -> 31.35 | R25: =((F25+G25*2)*0.15)*D25*E25 -> 3.585 | U25: =(F25+G25*2)*H25*D25*E25 -> 102.77 | V25: =N25 -> 31.35 | AG25: CEILING
B26: D15 | D26: -1 | E26: 1 | F26: 1.35 | H26: 2.2 | N26: =F26*G26*D26*E26 -> 0 | R26: =((F26+G26*2)*0.15)*E26*D26 -> -0.2025 | U26: =(F26+G26*2)*H26*D26*E26 -> -2.97 | V26: =N26 -> 0 | AG26: TYPE | AH26: DESCRIPTION
B27: Shop 2 | C27: SQ M | D27: 1 | E27: 1 | F27: 3.25 | G27: 9.6 | H27: 4.3 | N27: =F27*G27*D27*E27 -> 31.2 | R27: =((F27+G27*2)*0.15)*D27*E27 -> 3.3675 | U27: =(F27+G27*2)*H27*D27*E27 -> 96.535 | V27: =N27 -> 31.2 | AG27: C1 | AH27: 1 COAT PRIMER +2 COATS OF PUTTY + 3 COATS OF FENOMASTIC GOLD PAINT OR EQUIVALENT (COLOR SHALL BE FROM AS APPROVED BY ENGINEER)
B28: D15 | D28: -1 | E28: 1 | F28: 1.56 | H28: 2.2 | N28: =F28*G28*D28*E28 -> 0 | R28: =((F28+G28*2)*0.15)*E28*D28 -> -0.234 | U28: =(F28+G28*2)*H28*D28*E28 -> -3.432 | V28: =N28 -> 0 | AG28: C2 | AH28: DECORATIVE SUSPENDED FIRE RESISTANT 12mm THICK GYPSUM BOARD (DANOGIPS OR EQUIVALENT) CEILING FIXED WITH CONCEALED METAL SUSPENSION SYSTEM FIXED TO THE SOFFIT OF SLAB/BEAM OR TO WALL ALL BOARD JOINTS TO BE TAPED AND SKIMMED AND PAINTED AS STANDARD IN C2
B29: Shop 3 | C29: SQ M | D29: 1 | E29: 1 | F29: 3 | G29: 12.1 | H29: 4.3 | N29: =F29*G29*D29*E29 -> 36.3 | R29: =((F29+G29*2)*0.15)*D29*E29 -> 4.08 | U29: =(F29+G29*2)*H29*D29*E29 -> 116.96 | V29: =N29 -> 36.3
B30: D2 | D30: -1 | E30: 1 | F30: 1.8 | H30: 2.2 | N30: =F30*G30*D30*E30 -> 0 | R30: =((F30+G30*2)*0.15)*E30*D30 -> -0.27 | U30: =(F30+G30*2)*H30*D30*E30 -> -3.96 | V30: =N30 -> 0
B31: Shop 4,5,6,7 | C31: SQ M | D31: 1 | E31: 4 | F31: 2.7 | G31: 11.1 | H31: 4.3 | N31: =F31*G31*D31*E31 -> 119.88 | R31: =((F31+G31*2)*0.15)*D31*E31 -> 14.94 | U31: =(F31+G31*2)*H31*D31*E31 -> 428.28 | V31: =N31 -> 119.88
B32: D2 | D32: -1 | E32: 1 | F32: 1.8 | H32: 2.2 | N32: =F32*G32*D32*E32 -> 0 | R32: =((F32+G32*2)*0.15)*E32*D32 -> -0.27 | U32: =(F32+G32*2)*H32*D32*E32 -> -3.96 | V32: =N32 -> 0
B33: Shop 8 | C33: SQ M | D33: 1 | E33: 1 | F33: 3 | G33: 8.1 | H33: 4.3 | N33: =F33*G33*D33*E33 -> 24.3 | R33: =((F33+G33*2)*0.15)*D33*E33 -> 2.88 | U33: =(F33+G33*2)*H33*D33*E33 -> 82.56 | V33: =N33 -> 24.3
B34: D2 | D34: -1 | E34: 1 | F34: 1.8 | H34: 2.2 | N34: =F34*G34*D34*E34 -> 0 | R34: =((F34+G34*2)*0.15)*E34*D34 -> -0.27 | U34: =(F34+G34*2)*H34*D34*E34 -> -3.96 | V34: =N34 -> 0
B35: Shop 9 | C35: SQ M | D35: 1 | E35: 1 | F35: 5.81 | G35: 5.81 | H35: 4.3 | N35: =F35*G35*D35*E35 -> 33.7561 | R35: =((F35+G35*2)*0.15)*D35*E35 -> 2.6145 | U35: =(F35+G35*2)*H35*D35*E35 -> 74.949 | V35: =N35 -> 33.7561
B36: D2 | D36: -1 | E36: 2 | F36: 1.8 | H36: 2.2 | N36: =F36*G36*D36*E36 -> 0 | R36: =((F36+G36*2)*0.15)*E36*D36 -> -0.54 | U36: =(F36+G36*2)*H36*D36*E36 -> -7.92 | V36: =N36 -> 0
B37: Shop 10 | C37: SQ M | D37: 1 | E37: 1 | F37: 2.7 | G37: 10.1 | H37: 4.3 | N37: =F37*G37*D37*E37 -> 27.27 | R37: =((F37+G37*2)*0.15)*D37*E37 -> 3.435 | U37: =(F37+G37*2)*H37*D37*E37 -> 98.47 | V37: =N37 -> 27.27
B38: D2 | D38: -1 | E38: 1 | F38: 1.8 | H38: 2.2 | N38: =F38*G38*D38*E38 -> 0 | R38: =((F38+G38*2)*0.15)*E38*D38 -> -0.27 | U38: =(F38+G38*2)*H38*D38*E38 -> -3.96 | V38: =N38 -> 0
B39: Shop 11 | C39: SQ M | D39: 1 | E39: 1 | F39: 2.75 | G39: 11 | H39: 4.3 | N39: =F39*G39*D39*E39 -> 30.25 | R39: =((F39+G39*2)*0.15)*D39*E39 -> 3.7125 | U39: =(F39+G39*2)*H39*D39*E39 -> 106.425 | V39: =N39 -> 30.25
B40: D2 | D40: -1 | E40: 1 | F40: 1.8 | H40: 2.2 | N40: =F40*G40*D40*E40 -> 0 | R40: =((F40+G40*2)*0.15)*E40*D40 -> -0.27 | U40: =(F40+G40*2)*H40*D40*E40 -> -3.96 | V40: =N40 -> 0
B41: Shop 12 | C41: SQ M | D41: 1 | E41: 1 | F41: 3.3 | G41: 11.9 | H41: 4.3 | N41: =F41*G41*D41*E41 -> 39.27 | R41: =((F41+G41*2)*0.15)*D41*E41 -> 4.065 | U41: =(F41+G41*2)*H41*D41*E41 -> 116.53 | V41: =N41 -> 39.27
B42: D2 | D42: -1 | E42: 1 | F42: 1.8 | H42: 2.2 | N42: =F42*G42*D42*E42 -> 0 | R42: =((F42+G42*2)*0.15)*E42*D42 -> -0.27 | U42: =(F42+G42*2)*H42*D42*E42 -> -3.96 | V42: =N42 -> 0
...

Sheet M.S
A1: PROJECT:- RESIDENTIAL / COMMERCIAL BUILDING
A2: SUB:- Main bld measurement
R3: Blindings or P.C.C | V3: RCC works | Z3: Polythene sheet | AD3: Water proofing to RCC | AH3: isolation joint | AK3: Solid blockworks
A4: S.No | B4: Description | C4: Unit | D4: No | F4: L | G4: B | H4: D | I4: Qty | J4: If Irregular Area of Concrete | L4: If Irregular perimeter form works | N4: Remarks | P4: Blindings | R4: Concrete | T4: Shuttering | V4: Concrete | X4: Shuttering | Z4: Bottom of P.C.C | AA4: Sides of P.C.C | AD4: Bottom of RCC | AE4: Sides of RCC | AF4: Top of RCC | AH4: sides of grade slab and plinth | AK4: Masonry works | AM4: BRC mesh | AO4: Construction joint
J5: PCC | K5: RCC | L5: PCC | M5: RCC | P5: Thk | Q5: Offset | R5: P.C.C shape ''m3'' | S5: P.C.C Irregular ''m3'' | T5: P.C.C shape ''m2'' | U5: P.C.C Irregular ''m2'' | V5: R.C.C shape ''m3'' | W5: R.C.C Irregular ''m3'' | X5: R.C.C shape ''m2'' | Y5: R.C.C Irregular ''m2'' | Z5: Bottom''m2'' | AA5: Sides and Top''m2'' | AD5: Bottom''m2'' | AE5: Sides''m2'' | AF5: Top''m2'' | AH5: R.C.C shape ''m'' | AI5: R.C.C Irregular ''m'' | AK5: Externally | AL5: Internally | AM5: R.C.C shape ''m2'' | AN5: R.C.C Irregular ''m2'' | AO5: Vertical | AP5: Horizontally
B7: Earth works
B8: Footing base | C8: m3 | D8: 1 | E8: 1 | F8: 32.1 | G8: 23.43 | H8: 6.95 | I8: =PRODUCT(D8:H8) -> 5227.1159
B10: Total | I10: =SUM(I8:I9) -> 5227.1159
B12: Back filling
B13: Total excavated | C13: m3 | D13: 1 | E13: 1 | F13: =I10 -> 5227.1159 | I13: =PRODUCT(D13:H13) -> 5227.1159
B14: Deduction
B15: Basement deduction | C15: m3 | D15: 1 | E15: 1 | F15: 0 | H15: 0 | I15: =PRODUCT(D15:H15) -> 0
B16: Workikng space filling afterwork | C16: m3 | D16: 1 | E16: 1 | F16: 0 | G16: 0 | H16: =H15 -> 0 | I16: =PRODUCT(D16:H16) -> 0
B17: Above NGL Filling if Any
B19: Total | I19: =SUM(I13:I18) -> 5227.1159
B21: Grave Filling | C21: m3 | D21: 1 | E21: 1 | F21: 0 | G21: 0 | H21: 0 | I21: =PRODUCT(D21:H21) -> 0
B23: Total | I23: =SUM(I21:I22) -> 0
B25: Concrete works
B26: Foundation
B27: Footing or raft | C27: m3 | D27: 1 | E27: 1 | F27: 32.1 | G27: 23.43 | H27: 0.8 | J27: =875+(121*0.1)+(33*0.1) -> 890.4 | K27: 875 | L27: 121 | M27: 120 | P27: 0.1 | Q27: 0.1 | R27: =(((F27+Q27*2)*(G27+Q27*2))*P27)*E27*D27 -> 76.3249 | S27: =((J27*P27)*E27*D27) -> 89.04 | T27: =((((F27+Q27*2)+(G27+Q27*2))*2)*P27)*E27*D27 -> 11.186 | U27: =((L27*P27)*E27*D27) -> 12.1 | V27: =(((F27*G27*H27)*E27*D27)) -> 601.6824 | W27: =((K27*H27)*E27*D27) -> 700 | X27: =((F27*2+G27*2)*H27)*E27*D27 -> 88.848 | Y27: =((M27*H27)*E27*D27) -> 96 | Z27: =(R27/P27)+(S27/P27) -> 1653.649 | AA27: =(T27*2+U27*2) -> 46.572 | AD27: =(((F27*G27)*E27*D27))+K27 -> 1627.103 | AE27: =(X27+Y27) -> 184.848 | AF27: =AD27 -> 1627.103
B28: lift pit concrete section 5-5 | C28: m3 | D28: 1 | E28: 1
B29: lift pit concrete section 6-6 | C29: m3 | D29: 1 | E29: 1
B31: Total | R31: =SUM(R27:R30) -> 76.3249 | S31: =SUM(S27:S30) -> 89.04 | T31: =SUM(T27:T30) -> 11.186 | U31: =SUM(U27:U30) -> 12.1 | V31: =SUM(V27:V30) -> 601.6824 | W31: =SUM(W27:W30) -> 700 | X31: =SUM(X27:X30) -> 88.848 | Y31: =SUM(Y27:Y30) -> 96 | ... AA31: =SUM(AA27:AA30) -> 46.572 | AD31: =SUM(AD27:AD30) -> 1627.103 | AE31: =SUM(AE27:AE30) -> 184.848 | AF31: =SUM(AF27:AF30) -> 1627.103 | AH31: =SUM(AH27:AH30) -> 0 | AI31: =SUM(AI27:AI30) -> 0 | AK31: =SUM(AK27:AK30) -> 0 | AL31: =SUM(AL27:AL30) -> 0
B33: Stub column or pedestals
B35: Column
B36: C1 | C36: m3 | D36: 1 | E36: 11 | F36: 0.4 | G36: 0.8 | H36: =$H$8-$H$27 -> 6.15 | I36: =PRODUCT(D36:G36) -> 3.52 | V36: =PRODUCT(D36:H36) -> 21.648 | W36: =((K36*H36)*E36*D36) -> 0 | X36: =((F36*2+G36*2)*H36)*E36*D36 -> 162.36 | Y36: =((M36*H36)*E36*D36) -> 0 | AE36: =(X36+Y36) -> 162.36 | AF36: =(V36/H36)+(W36/H36) -> 3.52 | AH36: =(G36*2)*E36*D36 -> 17.6 | AI36: =(M36*E36*D36) -> 0
B37: C2 | C37: m3 | D37: 1 | E37: 7 | F37: 0.4 | G37: 0.8 | H37: =$H$8-$H$27 -> 6.15 | I37: =PRODUCT(D37:G37) -> 2.24 | V37: =PRODUCT(D37:H37) -> 13.776 | W37: =((K37*H37)*E37*D37) -> 0 | X37: =((F37*2+G37*2)*H37)*E37*D37 -> 103.32 | Y37: =((M37*H37)*E37*D37) -> 0 | AE37: =(X37+Y37) -> 103.32 | AF37: =(V37/H37)+(W37/H37) -> 2.24 | AH37: =(G37*2)*E37*D37 -> 11.2 | AI37: =(M37*E37*D37) -> 0
B38: C3 | C38: m3 | D38: 1 | E38: 2 | F38: 0.4 | G38: 0.9 | H38: =$H$8-$H$27 -> 6.15 | I38: =PRODUCT(D38:G38) -> 0.72 | V38: =PRODUCT(D38:H38) -> 4.428 | W38: =((K38*H38)*E38*D38) -> 0 | X38: =((F38*2+G38*2)*H38)*E38*D38 -> 31.98 | Y38: =((M38*H38)*E38*D38) -> 0 | AF38: =(V38/H38)+(W38/H38) -> 0.72
B39: C4 | C39: m3 | D39: 1 | E39: 2 | F39: 0.4 | G39: 0.75 | H39: =$H$8-$H$27 -> 6.15 | I39: =PRODUCT(D39:G39) -> 0.6 | V39: =PRODUCT(D39:H39) -> 3.69 | W39: =((K39*H39)*E39*D39) -> 0 | X39: =((F39*2+G39*2)*H39)*E39*D39 -> 28.29 | Y39: =((M39*H39)*E39*D39) -> 0 | AF39: =(V39/H39)+(W39/H39) -> 0.6
B40: C5 | C40: m3 | D40: 1 | E40: 6 | F40: 0.5 | G40: 0.9 | H40: =$H$8-$H$27 -> 6.15 | I40: =PRODUCT(D40:G40) -> 2.7 | V40: =PRODUCT(D40:H40) -> 16.605 | W40: =((K40*H40)*E40*D40) -> 0 | X40: =((F40*2+G40*2)*H40)*E40*D40 -> 103.32 | Y40: =((M40*H40)*E40*D40) -> 0 | AF40: =(V40/H40)+(W40/H40) -> 2.7
B41: C* | C41: m3 | D41: 1 | E41: 2 | F41: 0.4 | G41: 0.4 | H41: =$H$8-$H$27 -> 6.15 | I41: =PRODUCT(D41:G41) -> 0.32 | V41: =PRODUCT(D41:H41) -> 1.968 | W41: =((K41*H41)*E41*D41) -> 0 | X41: =((F41*2+G41*2)*H41)*E41*D41 -> 19.68 | Y41: =((M41*H41)*E41*D41) -> 0 | AF41: =(V41/H41)+(W41/H41) -> 0.32
B43: Total | E43: =SUM(E36:E42) -> 30 | R43: =SUM(R36:R42) -> 0 | S43: =SUM(S36:S42) -> 0 | T43: =SUM(T36:T42) -> 0 | U43: =SUM(U36:U42) -> 0 | V43: =SUM(V36:V42) -> 62.115 | W43: =SUM(W36:W42) -> 0 | X43: =SUM(X36:X42) -> 448.95 | Y43: =SUM(Y36:Y42) -> 0 | ... AA43: =SUM(AA36:AA42) -> 0 | AD43: =SUM(AD36:AD42) -> 0 | AE43: =SUM(AE36:AE42) -> 265.68 | AF43: =SUM(AF36:AF42) -> 10.1 | AH43: =SUM(AH36:AH42) -> 28.8 | AI43: =SUM(AI36:AI42) -> 0 | AK43: =SUM(AK36:AK42) -> 0 | AL43: =SUM(AL36:AL42) -> 0
B45: Stub column of GF
B47: Column
B48: C1 | C48: m3 | D48: 1 | E48: 11 | F48: 0.4 | G48: 0.8 | H48: =4.65-0.3 -> 4.35 | I48: =PRODUCT(D48:G48) -> 3.52 | V48: =PRODUCT(D48:H48) -> 15.312 | W48: =((K48*H48)*E48*D48) -> 0 | X48: =((F48*2+G48*2)*H48)*E48*D48 -> 114.84 | Y48: =((M48*H48)*E48*D48) -> 0 | AE48: =(X48+Y48) -> 114.84 | AF48: =(V48/H48)+(W48/H48) -> 3.52 | AH48: =(G48*2)*E48*D48 -> 17.6 | AI48: =(M48*E48*D48) -> 0
B49: C2 | C49: m3 | D49: 1 | E49: 7 | F49: 0.4 | G49: 0.8 | H49: =4.65-0.3 -> 4.35 | I49: =PRODUCT(D49:G49) -> 2.24 | V49: =PRODUCT(D49:H49) -> 9.744 | W49: =((K49*H49)*E49*D49) -> 0 | X49: =((F49*2+G49*2)*H49)*E49*D49 -> 73.08 | Y49: =((M49*H49)*E49*D49) -> 0 | AE49: =(X49+Y49) -> 73.08 | AF49: =(V49/H49)+(W49/H49) -> 2.24 | AH49: =(G49*2)*E49*D49 -> 11.2 | AI49: =(M49*E49*D49) -> 0
B50: C3 | C50: m3 | D50: 1 | E50: 2 | F50: 0.4 | G50: 0.9 | H50: =4.65-0.3 -> 4.35 | I50: =PRODUCT(D50:G50) -> 0.72 | V50: =PRODUCT(D50:H50) -> 3.132 | W50: =((K50*H50)*E50*D50) -> 0 | X50: =((F50*2+G50*2)*H50)*E50*D50 -> 22.62 | Y50: =((M50*H50)*E50*D50) -> 0 | AF50: =(V50/H50)+(W50/H50) -> 0.72
B51: C4 | C51: m3 | D51: 1 | E51: 2 | F51: 0.4 | G51: 0.75 | H51: =4.65-0.3 -> 4.35 | I51: =PRODUCT(D51:G51) -> 0.6 | V51: =PRODUCT(D51:H51) -> 2.61 | W51: =((K51*H51)*E51*D51) -> 0 | X51: =((F51*2+G51*2)*H51)*E51*D51 -> 20.01 | Y51: =((M51*H51)*E51*D51) -> 0 | AF51: =(V51/H51)+(W51/H51) -> 0.6
B52: C5 | C52: m3 | D52: 1 | E52: 6 | F52: 0.5 | G52: 0.9 | H52: =4.65-0.3 -> 4.35 | I52: =PRODUCT(D52:G52) -> 2.7 | V52: =PRODUCT(D52:H52) -> 11.745 | W52: =((K52*H52)*E52*D52) -> 0 | X52: =((F52*2+G52*2)*H52)*E52*D52 -> 73.08 | Y52: =((M52*H52)*E52*D52) -> 0 | AF52: =(V52/H52)+(W52/H52) -> 2.7
B53: C* | C53: m3 | D53: 1 | E53: 2 | F53: 0.4 | G53: 0.4 | H53: =4.65-0.3 -> 4.35 | I53: =PRODUCT(D53:G53) -> 0.32 | V53: =PRODUCT(D53:H53) -> 1.392 | W53: =((K53*H53)*E53*D53) -> 0 | X53: =((F53*2+G53*2)*H53)*E53*D53 -> 13.92 | Y53: =((M53*H53)*E53*D53) -> 0 | AF53: =(V53/H53)+(W53/H53) -> 0.32
...

Sheet Bill No. 4 Ancillary
A2: BILL NO. 4 - ANCILLARY
C3: Holding Tank
A4: ITEM | B4: ITEM DESCRIPTION | E4: QTY. | F4: UNIT | G4: RATE | H4: AMOUNT | J4: Calculated Qty
A5: REF. | H5: ( R.O. )
C7: CIVIL WORKS
C8: Holding tank & Fire Tank
C9: Concrete Work
C10: SRC reinforced pre-mixed cement concrete, Grade 40N/mm² as specified including placing, vibrating, curing and cube tests, etc.,
A12: A | C12: Base, wall, slab | E12: =J12 -> 47.92625 | F12: m3 | G12: 19.75 | H12: =+G12*E12 -> 946.54344 | J12: =M.S!I296+M.S!I297+M.S!I302+M.S!I303 -> 47.92625
C14: Formwork
A15: B | C15: Base, wall, slab | E15: =J15 -> 33.757 | F15: m2 | G15: 2 | H15: =+G15*E15 -> 67.514 | J15: =M.S!X299+M.S!X305 -> 33.757
C17: Reinforcement Works
C18: High yield steel deformed bar reinforcement BS 4449 (Grade Fe 500) of all including cutting, bending, fixing in position, binding wire, chairs, spacers, extra bars at cutouts/opening and protection against rusting etc as per structural drawing and schedule
A20: C | C20: 8mm - 32mm diameter bars | E20: =J20 -> 4914.756 | F20: Kgs | G20: 0.295 | H20: =+G20*E20 -> 1449.853 | J20: =4680.72*1.05 -> 4914.756
C22: Moisture Protection
C23: External between two RCC for floor and wall
A24: D | C24: Waterproofing and filler board | E24: =J24 -> 33.757 | F24: m2 | G24: 3.6 | H24: =+G24*E24 -> 121.5252 | J24: =M.S!AE299+M.S!AE305 -> 33.757
C26: internally waterproofing to holding tank
A27: E | C27: internal waterproofing to holding tank | E27: =J27 -> 33.757 | F27: m2 | G27: 2 | H27: =+G27*E27 -> 67.514 | J27: =J24 -> 33.757
A29: F | C29: Water bars | E29: =J29 -> 34.42 | F29: m | G29: 2 | H29: =+G29*E29 -> 68.84 | J29: =4.05*2+3.98*4+5.2*2 -> 34.42
A31: G | C31: Manhole cover | E31: =J31 -> 4 | F31: No | G31: 45 | H31: =+G31*E31 -> 180 | J31: 4
C32: To Collection | G32: R.O.
H33: =SUM(H6:H32) -> 2901.7897
C34: TOTAL FOR BILL NO.4 ANCILLARY- CARRIED TO GENERAL SUMMARY | G34: R.O.
H35: =+H33 -> 2901.7897

Sheet Bill No.5 Electrical & ELV
A2: BILL NO. 5 - Electrical & ELV
A4: ITEM | B4: ITEM DESCRIPTION | E4: QTY. | F4: UNIT | G4: RATE | H4: AMOUNT
A5: REF. | H5: ( R.O. )
C7: ELECTRICAL INSTALLATION
C9: MAINS INSTALLATIONS
C11: SUB MAINS INSTALLATIONS
C13: Supply and install LV panels with control gear, as specified, complete with volt selection switches, voltmeters, indicator lamps , all as shown on drawings. Complete all in accordance with standard OES-4 specifications.
A15: 1 | C15: Feeder pillar | E15: 1 | F15: Nr. | H15: =G15*E15 -> 0
A17: 2 | C17: MDB -1 | E17: 1 | F17: Nr. | G17: 1857 | H17: =G17*E17 -> 1857
A19: 3 | C19: MDB -2 | E19: 1 | F19: Nr. | G19: 1307 | H19: =G19*E19 -> 1307
A21: 4 | C21: MDB -3 | E21: 1 | F21: Nr. | G21: 1203 | H21: =G21*E21 -> 1203
C23: EARTHING
A25: 1 | C25: Earthing as per MEDC sandard ,as specified to LV power supply and distribution installtion including necessary accessories (Civil work not included) | E25: 1 | F25: L/S | G25: 150 | H25: =G25*E25 -> 150
A27: 2 | C27: Rubber mat for Electrical room | E27: 1 | F27: L/S | G27: 80 | H27: =G27*E27 -> 80
C28: To Collection
C29: To Collection | G29: R.O. | H29: =SUM(H14:H28) -> 4597
C31: ELECTRICAL INSTALLATION (CONT'D.)
C32: Supply and install quipment and control gear, as specified and detailed on drawing. Including cable (not measured separately) & cable terminations, cable trays from proposed panel to Distribution Board Complete all in accordance with drawings and standard OES-4 specifications.
C33: Distribution Board
C34: GROUND FLOOR
A36: 1 | C36: DB GC - 16 WAY TPN | E36: 1 | F36: Nr. | H36: =G36*E36 -> 0
A38: 2 | C38: DB SH 1 - 14 WAY SPN | E38: 1 | F38: Nr. | H38: =G38*E38 -> 0
A40: 3 | C40: DB SH 2 - 14 WAY SPN | E40: 1 | F40: Nr. | H40: =G40*E40 -> 0
A42: 4 | C42: DB SH 3 - 14 WAY SPN | E42: 1 | F42: Nr. | H42: =G42*E42 -> 0
A44: 5 | C44: DB SH 4 - 14 WAY SPN | E44: 1 | F44: Nr. | H44: =G44*E44 -> 0
A46: 6 | C46: DB SH 5 - 14 WAY SPN | E46: 1 | F46: Nr. | H46: =G46*E46 -> 0
A48: 7 | C48: DB SH 6 - 14 WAY SPN | E48: 1 | F48: Nr. | H48: =G48*E48 -> 0
A50: 8 | C50: DB SH 7 - 14 WAY SPN | E50: 1 | F50: Nr. | H50: =G50*E50 -> 0
A52: 9 | C52: DB SH 8 - 14 WAY SPN | E52: 1 | F52: Nr. | H52: =G52*E52 -> 0
A54: 10 | C54: DB SH 9 - 14 WAY SPN | E54: 1 | F54: Nr. | H54: =G54*E54 -> 0
A56: 11 | C56: DB SH 10 - 14 WAY SPN | E56: 1 | F56: Nr. | H56: =G56*E56 -> 0
A58: 12 | C58: DB SH 11 - 14 WAY SPN | E58: 1 | F58: Nr. | H58: =G58*E58 -> 0
... A70: 18 | C70: DB SH 17 - 14 WAY SPN | E70: 1 | F70: Nr. | H70: =G70*E70 -> 0
C72: FIRST FLOOR TO FIFTH FLOOR
A74: 1 | C74: DB-1F1 - 16 WAY SPN (TYP) | E74: 5 | F74: Nr. | H74: =SUM(G74*E74) -> 0
A76: 2 | C76: DB-1F2 - 16 WAY SPN (TYP) | E76: 5 | F76: Nr. | H76: =SUM(G76*E76) -> 0
A78: 3 | C78: DB-1F3 - 16 WAY SPN (TYP) | E78: 5 | F78: Nr. | H78: =SUM(G78*E78) -> 0
A80: 4 | C80: DB-1F4 - 16 WAY SPN (TYP) | E80: 5 | F80: Nr. | H80: =SUM(G80*E80) -> 0
A82: 5 | C82: DB-1F5 - 16 WAY SPN (TYP) | E82: 5 | F82: Nr. | H82: =SUM(G82*E82) -> 0
A84: 6 | C84: DB-1F6 - 16 WAY SPN (TYP) | E84: 5 | F84: Nr. | H84: =SUM(G84*E84) -> 0
...

Sheet Bill No.6 Plumbing
A2: BILL NO. 6 - Plumbing Installations
A4: ITEM | B4: ITEM DESCRIPTION | E4: QTY. | F4: UNIT | G4: RATE | H4: AMOUNT
A5: REF. | H5: ( R.O. )
C7: PLUMBING INSTALLATIONS
C9: DRAINAGE INSTALLATIONS
C11: DRAINAGE PIPING (BM & GF)
C13: Supply, install; Unplasticized Polyvinyl chloride (uPVC) pipe; above ground confirming to BS 4514 for above ground and BS 4660 for below ground piping including all supports fittings, markings, excavation, bedding, backfilling, concrete encasement (where required).
A15: 1 | C15: 200 mm diameter SP | E15: =6*1.5 -> 9 | F15: M | G15: 2.7 | H15: =G15*E15 -> 24.3
A17: 2 | C17: 200 mm diameter WP | E17: =6*1.5 -> 9 | F17: M | G17: 2.7 | H17: =G17*E17 -> 24.3
A19: 3 | C19: 110 mm diameter SP | E19: =57*1.5 -> 85.5 | F19: M | G19: 0.5 | H19: =G19*E19 -> 42.75
A21: 4 | C21: 110 mm diameter WP | E21: =65*1.5 -> 97.5 | F21: M | G21: 0.5 | H21: =G21*E21 -> 48.75
A23: 5 | C23: 110 mm Roding Eye | E23: =10*1.5 -> 15 | F23: Nr | G23: 0.6 | H23: =G23*E23 -> 9
C25: STORM WATER SYSTEM
C26: Supply, install; Unplasticized Polyvinyl chloride (uPVC) pipe; above ground confirming to BS 4514 for above groundBS 4660 for below ground piping including all supports fittings, markings, excavation, bedding, backfilling, concrete encasement (where required).
A28: 1 | C28: 110 mm diameter (BM) | E28: =14*1.5 -> 21 | F28: M | G28: 0.6 | H28: =G28*E28 -> 12.6
A30: 2 | C30: 300 mm HD DI Chanel grating | E30: =15+9 -> 24 | F30: M | G30: 10 | H30: =G30*E30 -> 240
C31: To Collection
C32: To Collection | G32: R.O. | H32: =SUM(H6:H31) -> 401.7
C34: RAIN WATER SYSTEM
C35: Supply, install; Unplasticized Polyvinyl chloride (uPVC) pipe; above ground confirming to BS 4514 for above ground including all supports fittings, markings, excavation, bedding, backfilling, concrete encasement (where required).
A37: 1 | C37: 110 mm diameter RWP | E37: =20*1.5 -> 30 | F37: M | G37: 1.325 | H37: =G37*E37 -> 39.75
A39: 2 | C39: Rain water Outlet 110mm | E39: 4 | F39: Nr | G39: 8 | H39: =G39*E39 -> 32
C41: SUMP PUMP
A43: 1 | C43: 25m3/hr @20m Head Duty/ Assist | E43: 1 | F43: Set | G43: 1400 | H43: =G43*E43 -> 1400
A45: 2 | C45: 110 mm Hpvc pipes and fittings | E45: 6 | F45: M | G45: 1.8 | H45: =G45*E45 -> 10.8
C47: DRAINAGE SYSTEM (SOIL & WASTE LINES)
C49: Supply, install; Unplasticized Polyvinyl chloride (uPVC) pipe; above ground confirming to BS 4514 for above groundBS 4660 for below ground piping including all supports fittings, markings, excavation, bedding, backfilling, concrete encasement (where required).
A51: 1 | C51: 160 mm diameter (GF & External) | E51: =97*1.1 -> 106.7 | F51: M | G51: 1.325 | H51: =G51*E51 -> 141.3775
A53: 2 | C53: 110 mm diameter SVP | E53: =25*2*6 -> 300 | F53: M | G53: 0.5 | H53: =G53*E53 -> 150
A55: 3 | C55: 110 mm diameter WVP | E55: =30*2*6+20 -> 380 | F55: M | G55: 0.5 | H55: =G55*E55 -> 190
A57: 4 | C57: 82 mm diameter WVP | E57: =16*2*6 -> 192 | F57: M | G57: 0.141 | H57: =G57*E57 -> 27.072
A59: 5 | C59: 55 mm diameter WVP | E59: =17*2*6 -> 204 | F59: M | G59: 0.083 | H59: =G59*E59 -> 16.932
A61: 6 | C61: 160 mm Roding Eye | E61: =11*1.25 -> 13.75 | F61: Nr | G61: 0.457 | H61: =G61*E61 -> 6.28375
A63: 7 | C63: 110 mm Roding Eye | E63: =4+26*6*1.1 -> 175.6 | F63: Nr | G63: 0.6 | H63: =G63*E63 -> 105.36
A65: 8 | C65: 82 mm Roding Eye | E65: =8*6*1.1 -> 52.8 | F65: Nr | G65: 0.3 | H65: =G65*E65 -> 15.84
A67: 9 | C67: 110 mm Vent Cowl | E67: =17*2*1.25 -> 42.5 | F67: Nr | G67: 0.4 | H67: =G67*E67 -> 17
C68: To Collection
C69: To Collection | G69: R.O. | H69: =SUM(H35:H68) -> 2152.4153
C71: HOLDING TANK INSTALLATION
A73: 1 | C73: 110 mm diameter HDPE Pipe (BOWSER) | E73: 7 | F73: M | G73: 2 | H73: =G73*E73 -> 14
...

Sheet BILL NO.9 PROVISIONAL
A2: BILL NO. 5 - Finishing Work Package
A4: Item | C4: Work Description | E4: Qty | F4: Unit | G4: Rate | H4: R.O. Bz.
C6: Finishing work Packages
C8: Allow for the following Provisional Sums to be expended as directed by the Engineer/Employer's Representative or deducted in whole or in part if not required
A10: A | C10: LIFT INSTALLATION | E10: 2 | F10: Nos | G10: 11250 | H10: =(E10*G10) -> 22500
A12: B | C12: Kitchen Cabinet including the appliances | E12: 54 | F12: Nos | G12: 600 | H12: =(E12*G12) -> 32400
A14: C | C14: EXTERNAL CAR PARKING | E14: 33 | F14: Nos | G14: 50 | H14: =(E14*G14) -> 1650
A16: D | C16: SHORING | E16: 1 | F16: Item | G16: 6500 | H16: =(E16*G16) -> 6500
A18: E | C18: PUZZLE CAR PARKING Mechanically operated and lifting Car lifting REFER DWG - A111 | E18: 1 | F18: Item | G18: 20000 | H18: =(E18*G18) -> 20000
A20: F | C20: Electrical Main Connection Works | E20: 1 | F20: Item | G20: 2000 | H20: =(E20*G20) -> 2000
A22: G | C22: Waterline Main Connection Works including FEES | E22: 1 | F22: Item | G22: 1650 | H22: =(E22*G22) -> 1650
A24: H | C24: HVAC Package | E24: 1 | F24: Items | G24: 35000 | H24: =(E24*G24) -> 35000
A26: I | C26: Fire Alarm & Fire Fighting works | E26: 1 | F26: Items | G26: 10000 | H26: =(E26*G26) -> 10000
A28: J | C28: Swimming Pool | E28: 1 | F28: Items | G28: 8000 | H28: =(E28*G28) -> 8000
A30: K | C30: Swimming Pool Deck | E30: 1 | F30: Items | G30: 3000 | H30: =(E30*G30) -> 3000
A32: L | C32: GYM | E32: 1 | F32: Items | G32: 10000 | H32: =(E32*G32) -> 10000
C37: PROVISIONAL SUMS
C38: Carried to General Summary | F38: R.O. | H38: =SUM(H10:H37) -> 152700

Sheet BW
A1: Project
A2: sub-masonry works
A4: S.No | B4: Description | C4: Unit | D4: No | F4: L | G4: B | H4: D | I4: Remarks | K4: 300mm hick | L4: 200mm thick | M4: 100mm thick
B5: Basement 01 floor
B6: 300mm thick | C6: m2 | D6: 1 | E6: 1 | F6: 6.95 | H6: =4.35-0.7 -> 3.65 | K6: =PRODUCT(D6:H6) -> 25.3675
B7: 200mm thick | C7: m2 | D7: 1 | E7: 2 | F7: 3 | H7: =4.35-0.7 -> 3.65 | L7: =PRODUCT(D7:H7) -> 21.9
B8: 200mm thick | C8: m2 | D8: 1 | E8: 3 | F8: 6.95 | H8: =4.35-0.7 -> 3.65 | L8: =PRODUCT(D8:H8) -> 76.1025
B9: 200mm thick | C9: m2 | D9: 1 | E9: 2 | F9: 1.1 | H9: =4.35-0.7 -> 3.65 | L9: =PRODUCT(D9:H9) -> 8.03
B10: 200mm thick | C10: m2 | D10: 1 | E10: 2 | F10: 2.2 | H10: =4.35-0.7 -> 3.65 | L10: =PRODUCT(D10:H10) -> 16.06
B11: 200mm thick | C11: m2 | D11: 1 | E11: 1 | F11: 1.26 | H11: =4.35-0.7 -> 3.65 | L11: =PRODUCT(D11:H11) -> 4.599
B12: 200mm thick | C12: m2 | D12: 1 | E12: 1 | F12: 2.5 | H12: =4.35-0.7 -> 3.65 | L12: =PRODUCT(D12:H12) -> 9.125
B13: 200mm thick | C13: m2 | D13: 1 | E13: 1 | F13: 5.72 | H13: 4.35 | L13: =PRODUCT(D13:H13) -> 24.882
B14: D5 | C14: m2 | D14: -1 | E14: ='D&W'!I5 -> 2 | F14: ='D&W'!BG7/1000 -> 1 | H14: ='D&W'!BH7/1000 -> 2.2 | L14: =PRODUCT(D14:H14) -> -4.4
B15: D10 | C15: m2 | D15: -1 | E15: ='D&W'!O5 -> 2 | F15: 1.1 | H15: 2.2 | L15: =PRODUCT(D15:H15) -> -4.84
B16: D3 | C16: m2 | D16: -1 | E16: 1 | F16: ='D&W'!BG5/1000 -> 1.5 | H16: 2.2 | L16: =PRODUCT(D16:H16) -> -3.3
B18: Ground floor
B19: 300mm thick | C19: m2 | D19: 1 | E19: 1 | F19: 1.15 | H19: 4.35 | K19: =PRODUCT(D19:H19) -> 5.0025
B20: 200mm thick | C20: m2 | D20: 1 | E20: 1 | F20: 4.84 | H20: =4.65-0.7 -> 3.95 | L20: =PRODUCT(D20:H20) -> 19.118
B21: 200mm thick | C21: m2 | D21: 1 | E21: 1 | F21: 0.75 | H21: =4.65-0.7 -> 3.95 | L21: =PRODUCT(D21:H21) -> 2.9625
B22: 200mm thick | C22: m2 | D22: 1 | E22: 1 | F22: 0.63 | H22: =4.65-0.7 -> 3.95 | L22: =PRODUCT(D22:H22) -> 2.4885
B23: 200mm thick | C23: m2 | D23: 1 | E23: 1 | F23: 10.25 | H23: =4.65-0.7 -> 3.95 | L23: =PRODUCT(D23:H23) -> 40.4875
B24: 200mm thick | C24: m2 | D24: 1 | E24: 1 | F24: 10.76 | H24: =4.65-0.3 -> 4.35 | L24: =PRODUCT(D24:H24) -> 46.806
B25: 200mm thick | C25: m2 | D25: 1 | E25: 2 | F25: 0.37 | H25: =4.65-0.3 -> 4.35 | L25: =PRODUCT(D25:H25) -> 3.219
B26: 200mm thick | C26: m2 | D26: 1 | E26: 1 | F26: 0.5 | H26: =4.65-0.3 -> 4.35 | L26: =PRODUCT(D26:H26) -> 2.175
B27: 200mm thick | C27: m2 | D27: 1 | E27: 1 | F27: 6.8 | H27: =4.65-0.3 -> 4.35 | L27: =PRODUCT(D27:H27) -> 29.58
B28: 200mm thick | C28: m2 | D28: 1 | E28: 2 | F28: 3.6 | H28: =4.65-0.3 -> 4.35 | L28: =PRODUCT(D28:H28) -> 31.32
B29: 200mm thick | C29: m2 | D29: 1 | E29: 1 | F29: 5.47 | H29: =4.65-0.3 -> 4.35 | L29: =PRODUCT(D29:H29) -> 23.7945
B30: 200mm thick | C30: m2 | D30: 1 | E30: 1 | F30: 7.3 | H30: =4.65-0.3 -> 4.35 | L30: =PRODUCT(D30:H30) -> 31.755
B31: 200mm thick | C31: m2 | D31: 1 | E31: 3 | F31: 5.49 | H31: =4.65-0.3 -> 4.35 | L31: =PRODUCT(D31:H31) -> 71.6445
B32: 200mm thick | C32: m2 | D32: 1 | E32: 1 | F32: 5.19 | H32: =4.65-0.3 -> 4.35 | L32: =PRODUCT(D32:H32) -> 22.5765
B33: 200mm thick | C33: m2 | D33: 1 | E33: 1 | F33: 4.53 | H33: =4.65-0.3 -> 4.35 | L33: =PRODUCT(D33:H33) -> 19.7055
B34: 200mm thick | C34: m2 | D34: 1 | E34: 1 | F34: 1.02 | H34: 4.35 | L34: =PRODUCT(D34:H34) -> 4.437
B35: 200mm thick | C35: m2 | D35: 1 | E35: 1 | F35: 3 | H35: 4.35 | L35: =PRODUCT(D35:H35) -> 13.05
B36: 200mm thick | C36: m2 | D36: 1 | E36: 1 | F36: 12 | H36: 4.35 | L36: =PRODUCT(D36:H36) -> 52.2
B37: 200mm thick | C37: m2 | D37: 1 | E37: 1 | F37: 1.2 | H37: 4.35 | L37: =PRODUCT(D37:H37) -> 5.22
B38: 200mm thick | C38: m2 | D38: 1 | E38: 1 | F38: 2.2 | H38: 4.35 | L38: =PRODUCT(D38:H38) -> 9.57
B39: 200mm thick | C39: m2 | D39: 1 | E39: 1 | F39: 1.3 | H39: 4.35 | L39: =PRODUCT(D39:H39) -> 5.655
B40: 200mm thick | C40: m2 | D40: 1 | E40: 1 | F40: 2 | H40: 4.35 | L40: =PRODUCT(D40:H40) -> 8.7
B41: 200mm thick | C41: m2 | D41: 1 | E41: 1 | F41: 2.7 | H41: 4.35 | L41: =PRODUCT(D41:H41) -> 11.745
B42: 200mm thick | C42: m2 | D42: 1 | E42: 1 | F42: 2.5 | H42: 4.35 | L42: =PRODUCT(D42:H42) -> 10.875
...

Sheet D&W
A2: S.No | B2: location | C2: D01 | D2: D02 | E2: D1 | F2: D2 | G2: D3 | H2: D4 | I2: D5 | J2: D6 | K2: D6* | L2: D7 | M2: D8 | N2: D9 | O2: D10 | P2: D11 | Q2: D12 | R2: D13 | S2: D14 | T2: D15 | U2: D16 | V2: D17 | W2: D18 | X2: W1 | Y2: W2 | Z2: W3 | AA2: W4 | AB2: W5 | AC2: W6 | AD2: W7 | AE2: W8 | AH2: CW1 | AI2: CW2 | AJ2: CW3 | AK2: CW4 | AL2: CW5 | AM2: CW6 | AN2: CW7 | AO2: CW8 | AP2: CW9 | AQ2: CW10 | AR2: CW11 | AS2: CW12 | AT2: CW13 | AU2: CW14 | AV2: CW15 | AW2: CW16 | AX2: CW17 | AY2: CW18 | AZ2: CW19 | BA2: CW20 | BB2: CW21 | BC2: CW22 | BD2: FG1 | BE2: FG | BF2: TYPE | BG2: SIZE (mm) - WIDTH | BH2: SIZE (mm) - HEIGHT | BI2: DESCRIPTION
BF3: D1 | BG3: 1700 | BH3: 2200 | BI3: HEAVY DUTY UPVC SECTION DOUBLE LEAF HINGED DOOR WITH 6mm DOUBLE GLASS 12 +mm AIR GAP IN BETWEEN
B4: Basement 2 | BF4: D2 | BG4: 1700 | BH4: 2200 | BI4: HEAVY DUTY UPVC SECTION DOUBLE LEAF HINGED DOOR WITH 6mm DOUBLE GLASS 12 +mm AIR GAP IN BETWEEN
B5: Basement 1 | G5: 1 | I5: 2 | O5: 2 | W5: 1 | BF5: D3 | BG5: 1500 | BH5: 2400 | BI5: HEAVY DUTY UPVC SECTION DOUBLE LEAF HINGED DOOR WITH 6mm DOUBLE GLASS 12 +mm AIR GAP IN BETWEEN
B6: Ground floor | E6: 1 | F6: 13 | H6: 1 | I6: 1 | J6: 2 | K6: 1 | L6: 1 | M6: 1 | O6: 3 | R6: 1 | S6: 1 | T6: 1 | U6: 1 | V6: 1 | AC6: 1 | AD6: 1 | BD6: 29 | BF6: D4 | BG6: 1000 | BH6: 2200 | BI6: MAHOGANY WOOD DECORATIVE PANELED SINGLE LEAF HINGED DOOR & 60min. FIRE RESISTANCE
B7: First floor | I7: 12 | J7: 10 | K7: 9 | M7: 9 | O7: 2 | P7: 14 | Q7: 11 | X7: 1 | Y7: 4 | Z7: 1 | AA7: 2 | AB7: 1 | AE7: 1 | AH7: 1 | AI7: 1 | AJ7: 1 | AK7: 1 | AL7: 1 | AM7: 1 | AN7: 1 | AO7: 1 | AP7: 1 | BE7: 14 | BF7: D5 | BG7: 1000 | BH7: 2200 | BI7: MAHOGANY WOOD DECORATIVE PANELED SINGLE LEAF HINGED DOOR
B8: Second floor | I8: 12 | J8: 10 | L8: 9 | N8: 9 | O8: 2 | P8: 14 | Q8: 11 | X8: 1 | Y8: 4 | Z8: 1 | AA8: 2 | AB8: 1 | AE8: 1 | AQ8: 1 | AR8: 1 | AS8: 1 | AT8: 1 | AU8: 1 | AV8: 1 | AW8: 1 | AX8: 1 | AY8: 1 | AZ8: 1 | BA8: 1 | BB8: 1 | BC8: 1 | BE8: 14 | BF8: D6 | BG8: 800 | BH8: 2200 | BI8: MAHOGANY WOOD DECORATIVE PANELED SINGLE LEAF HINGED DOOR WITH 300mm ALUMINUM PLATE
B9: Third floor | I9: 12 | J9: 10 | L9: 9 | N9: 9 | O9: 2 | P9: 14 | Q9: 11 | X9: 1 | Y9: 4 | Z9: 1 | AA9: 2 | AB9: 1 | AE9: 1 | AH9: 1 | AI9: 1 | AJ9: 1 | AK9: 1 | AL9: 1 | AM9: 1 | AN9: 1 | AO9: 1 | BE9: 14 | BF9: D6* | BG9: 1000 | BH9: 2200 | BI9: MAHOGANY WOOD DECORATIVE PANELED SINGLE LEAF HINGED DOOR WITH 300mm ALUMINUM PLATE
B10: Fourth floor | I10: 12 | J10: 10 | L10: 9 | N10: 9 | O10: 2 | P10: 14 | Q10: 11 | X10: 1 | Y10: 4 | Z10: 1 | AA10: 2 | AB10: 1 | AE10: 1 | AH10: 1 | AI10: 1 | AJ10: 1 | AK10: 1 | AL10: 1 | AM10: 1 | AN10: 1 | AO10: 1 | BE10: 14 | BF10: D7 | BG10: 800 | BH10: 2200 | BI10: HEAVY DUTY UPVC SECTION SINGLE LEAF HINGED DOOR WITH 6mm DOUBLE GLASS
B11: Fifth floor | I11: 12 | J11: 10 | L11: 9 | N11: 9 | O11: 2 | P11: 14 | Q11: 11 | X11: 1 | Y11: 4 | Z11: 1 | AA11: 2 | AB11: 1 | AE11: 1 | AH11: 1 | AI11: 1 | AJ11: 1 | AK11: 1 | AL11: 1 | AM11: 1 | AN11: 1 | AO11: 1 | BE11: 14 | BF11: D8 | BG11: 1000 | BH11: 2200 | BI11: HEAVY DUTY UPVC SECTION SINGLE LEAF HINGED DOOR GARBAGE ROOM | BK11: vv gy
B12: penthouse floor | I12: 12 | J12: 10 | L12: 9 | N12: 9 | O12: 2 | P12: 14 | Q12: 11 | X12: 1 | Y12: 4 | Z12: 1 | AA12: 2 | AB12: 1 | AE12: 1 | AH12: 1 | AI12: 1 | AJ12: 1 | AK12: 1 | AL12: 1 | AM12: 1 | AN12: 1 | AO12: 1 | BE12: 14 | BF12: D9 | BG12: 1100 | BH12: 2200 | BI12: MAHOGANY WOOD DECORATIVE PANELED SINGLE LEAF HINGED DOOR & 60min. FIRE RESISTANCE
B13: head room | O13: 2 | AB13: 2 | BF13: D10 | BG13: 1000 | BH13: 2200 | BI13: MAHOGANY WOOD DECORATIVE PANELED SINGLE LEAF HINGED DOOR & 90min. FIRE RESISTANCE
BF14: D11 | BG14: 1000 | BH14: 2200 | BI14: HEAVY DUTY UPVC SECTION SINGLE LEAF HINGED DOOR WITH 6mm DOUBLE GLASS
B15: Total | C15: =SUM(C4:C14) -> 0 | D15: =SUM(D4:D14) -> 0 | E15: =SUM(E4:E14) -> 1 | F15: =SUM(F4:F14) -> 13 | G15: =SUM(G4:G14) -> 1 | H15: =SUM(H4:H14) -> 1 | I15: =SUM(I4:I14) -> 75 | J15: =SUM(J4:J14) -> 62 | ... AE15: =SUM(AE4:AE14) -> 6 | AH15: =SUM(AH4:AH14) -> 5 | AI15: =SUM(AI4:AI14) -> 5 | AJ15: =SUM(AJ4:AJ14) -> 5 | AK15: =SUM(AK4:AK14) -> 5 | AL15: =SUM(AL4:AL14) -> 5 | AM15: =SUM(AM4:AM14) -> 5 | AN15: =SUM(AN4:AN14) -> 5 | AO15: =SUM(AO4:AO14) -> 5 | ... BE15: =SUM(BE4:BE14) -> 84 | BF15: D12 | BG15: 900 | BH15: 2200 | BI15: MAHOGANY WOOD DECORATIVE PANELED SINGLE LEAF HINGED DOOR WITH 300mm ALUMINUM PLATE
BF16: D13 | BG16: 1450 | BH16: 2200 | BI16: HEAVY DUTY UPVC SECTION SINGLE LEAF HINGED DOOR WITH 6mm DOUBLE GLASS 12 +mm AIR GAP IN BETWEEN
BF17: D14 | BG17: 1550 | BH17: 2200 | BI17: HEAVY DUTY UPVC SECTION DOUBLE LEAF HINGED DOOR WITH 6mm DOUBLE GLASS 12 +mm AIR GAP IN BETWEEN
BF18: D15 | BG18: 1350 | BH18: 2200 | BI18: HEAVY DUTY UPVC SECTION DOUBLE LEAF HINGED DOOR WITH 6mm DOUBLE GLASS 12 +mm AIR GAP IN BETWEEN
BF19: D16 | BG19: 1400 | BH19: 2200 | BI19: HEAVY DUTY UPVC SECTION DOUBLE LEAF HINGED DOOR WITH 6mm DOUBLE GLASS 12 +mm AIR GAP IN BETWEEN
B20: lintel | BF20: D17 | BG20: 1900 | BH20: 2200 | BI20: HEAVY DUTY UPVC SECTION DOUBLE LEAF HINGED DOOR WITH 6mm DOUBLE GLASS 12 +mm AIR GAP IN BETWEEN
B21: length | E21: {=TRANSPOSE((BG3:BG21 + 300) / 1000)} -> 2 | F21: 2 | G21: 1.8 | H21: 1.3 | I21: 1.3 | J21: 1.1 | K21: 1.3 | L21: 1.1 | M21: 1.3 | N21: 1.4 | O21: 1.3 | P21: 1.3 | Q21: 1.2 | R21: 1.75 | S21: 1.85 | T21: 1.65 | U21: 1.7 | V21: 2.2 | W21: 2.2 | X21: {=TRANSPOSE((BJ51:BJ55 + 300) / 1000)} -> 2.3 | Y21: 1.3 | Z21: 1.1 | AA21: 0.9 | AB21: 1.3 | AC21: 2 | AD21: 1.3 | AE21: 0.9 | BF21: D18 | BG21: 1900 | BH21: 2200 | BI21: HEAVY DUTY UPVC SECTION DOUBLE LEAF HINGED DOOR PUMP ROOM
B22: width | E22: 0.2 | F22: 0.2 | G22: 0.2 | H22: 0.2 | I22: 0.2 | J22: 0.2 | K22: 0.2 | L22: 0.2 | M22: 0.2 | N22: 0.2 | O22: 0.2 | P22: 0.2 | Q22: 0.2 | R22: 0.2 | S22: 0.2 | T22: 0.2 | U22: 0.2 | V22: 0.2 | W22: 0.2 | X22: 0.2 | Y22: 0.2 | Z22: 0.2 | AA22: 0.2 | AB22: 0.2 | AC22: 0.2 | AD22: 0.2 | AE22: 0.2
B23: depth | E23: 0.3 | F23: 0.3 | G23: 0.3 | H23: 0.3 | I23: 0.3 | J23: 0.3 | K23: 0.3 | L23: 0.3 | M23: 0.3 | N23: 0.3 | O23: 0.3 | P23: 0.3 | Q23: 0.3 | R23: 0.3 | S23: 0.3 | T23: 0.3 | U23: 0.3 | V23: 0.3 | W23: 0.3 | X23: 0.3 | Y23: 0.3 | Z23: 0.3 | AA23: 0.3 | AB23: 0.3 | AC23: 0.3 | AD23: 0.3 | AE23: 0.3 | BF23: SCHEDULE OF CURTAIN WALLS GLASS
BF24: TYPE | BG24: WIDTH (mm) | BH24: HEIGHT (mm) | BI24: GLASS 1 | BJ24: SILL LEVEL
B25: qty | E25: =PRODUCT(E21:E23)*E15 -> 0.12 | F25: =PRODUCT(F21:F23)*F15 -> 1.56 | G25: =PRODUCT(G21:G23)*G15 -> 0.108 | H25: =PRODUCT(H21:H23)*H15 -> 0.078 | I25: =PRODUCT(I21:I23)*I15 -> 5.85 | J25: =PRODUCT(J21:J23)*J15 -> 4.092 | K25: =PRODUCT(K21:K23)*K15 -> 0.78 | L25: =PRODUCT(L21:L23)*L15 -> 3.036 | ... AE25: =PRODUCT(AE21:AE23)*AE15 -> 0.324 | BF25: CW1 | BG25: 3050 | BH25: 3240 | BI25: H.Q UPVC SECTION WITH 6mm CLEAR FLOAT GLASS +12mm AIR GAP+6mm REFLECTED GLASS AWING WINDOW | BJ25: 0
B26: Cills | X26: =X25 -> 0.828 | Y26: =Y25 -> 1.872 | Z26: =Z25 -> 0.396 | AA26: =AA25 -> 0.648 | AB26: =AB25 -> 0.624 | AC26: =AC25 -> 0.12 | AD26: =AD25 -> 0.078 | AE26: =AE25 -> 0.324 | BF26: CW2 | BG26: 2100 | BH26: 3240 | BI26: H.Q UPVC SECTION WITH 6mm CLEAR FLOAT GLASS +12mm AIR GAP+6mm REFLECTED GLASS AWING WINDOW | BJ26: 0
B27: Area | E27: =E22*E21 -> 0.4 | F27: =F22*F21 -> 0.4 | G27: =G22*G21 -> 0.36 | H27: =H22*H21 -> 0.26 | I27: =I22*I21 -> 0.26 | J27: =J22*J21 -> 0.22 | K27: =K22*K21 -> 0.26 | L27: =L22*L21 -> 0.22 | ... AE27: =AE22*AE21 -> 0.18 | BF27: CW3 | BG27: 1400 | BH27: 3240 | BI27: H.Q UPVC SECTION WITH 6mm CLEAR FLOAT GLASS +12mm AIR GAP+6mm REFLECTED GLASS AWING WINDOW | BJ27: 0
B28: Total concrete | E28: =SUM(E25:E27)-E27 -> 0.12 | F28: =SUM(F25:F27)-F27 -> 1.56 | G28: =SUM(G25:G27)-G27 -> 0.108 | H28: =SUM(H25:H27)-H27 -> 0.078 | I28: =SUM(I25:I27)-I27 -> 5.85 | J28: =SUM(J25:J27)-J27 -> 4.092 | K28: =SUM(K25:K27)-K27 -> 0.78 | L28: =SUM(L25:L27)-L27 -> 3.036 | ... AE28: =SUM(AE25:AE27)-AE27 -> 0.648 | AF28: =SUM(C28:AE28) -> 43.431 | AG28: m3 | BF28: CW4 | BG28: 3400 | BH28: 3240 | BI28: H.Q UPVC SECTION WITH 6mm CLEAR FLOAT GLASS +12mm AIR GAP+6mm REFLECTED GLASS AWING WINDOW | BJ28: 0
BF29: CW5 | BG29: 2600 | BH29: 3240 | BI29: H.Q UPVC SECTION WITH 6mm CLEAR FLOAT GLASS +12mm AIR GAP+6mm REFLECTED GLASS AWING WINDOW | BJ29: 0
BF30: CW6 | BG30: 3050 | BH30: 3240 | BI30: H.Q UPVC SECTION WITH 6mm CLEAR FLOAT GLASS +12mm AIR GAP+6mm REFLECTED GLASS AWING WINDOW | BJ30: 0
B31: Cw | AH31: =AH2 -> CW1 | AI31: =AI2 -> CW2 | AJ31: =AJ2 -> CW3 | AK31: =AK2 -> CW4 | AL31: =AL2 -> CW5 | AM31: =AM2 -> CW6 | AN31: =AN2 -> CW7 | AO31: =AO2 -> CW8 | ... BC31: =BC2 -> CW22 | BF31: CW7 | BG31: 1500 | BH31: 3240 | BI31: H.Q UPVC SECTION WITH 6mm CLEAR FLOAT GLASS +12mm AIR GAP+6mm REFLECTED GLASS AWING WINDOW | BJ31: 0
B32: Width(m) | AH32: {=TRANSPOSE((BG25:BG47) / 1000)} -> 3.05 | AI32: 2.1 | AJ32: 1.4 | AK32: 3.4 | AL32: 2.6 | AM32: 3.05 | AN32: 1.5 | AO32: 1.9 | AP32: 2.3 | AQ32: 1.95 | AR32: 1.6 | AS32: 1.7 | AT32: 1.4 | AU32: 2.1 | AV32: 0.8 | AW32: 0.9 | AX32: 0.8 | AY32: 2.35 | AZ32: 1.3 | BA32: 0 | BB32: 1.7 | BC32: 0.6 | BD32: 1.3 | BF32: CW8 | BG32: 1900 | BH32: 3200 | BI32: H.Q UPVC SECTION WITH 6mm CLEAR FLOAT GLASS +12mm AIR GAP+6mm REFLECTED GLASS AWING WINDOW | BJ32: 0
B33: Height(m) | AH33: {=TRANSPOSE((BH25:BH47) / 1000)} -> 3.24 | AI33: 3.24 | AJ33: 3.24 | AK33: 3.24 | AL33: 3.24 | AM33: 3.24 | AN33: 3.24 | AO33: 3.2 | AP33: 3.2 | AQ33: 3.24 | AR33: 3.24 | AS33: 3.24 | AT33: 3.24 | AU33: 3.24 | AV33: 3.24 | AW33: 3.24 | AX33: 3.24 | AY33: 3.24 | AZ33: 3.24 | BA33: 0 | BB33: 3.2 | BC33: 3.2 | BD33: 3.2 | BF33: CW9 | BG33: 2300 | BH33: 3200 | BI33: H.Q UPVC SECTION WITH 6mm CLEAR FLOAT GLASS +12mm AIR GAP+6mm REFLECTED GLASS AWING WINDOW | BJ33: 0
BF34: CW10 | BG34: 1950 | BH34: 3240 | BI34: H.Q UPVC SECTION WITH 6mm CLEAR FLOAT GLASS +12mm AIR GAP+6mm REFLECTED GLASS AWING WINDOW | BJ34: 0
B35: Nos | AH35: =AH15 -> 5 | AI35: =AI15 -> 5 | AJ35: =AJ15 -> 5 | AK35: =AK15 -> 5 | AL35: =AL15 -> 5 | AM35: =AM15 -> 5 | AN35: =AN15 -> 5 | AO35: =AO15 -> 5 | ... BC35: =BC15 -> 1 | BF35: CW11 | BG35: 1600 | BH35: 3240 | BI35: H.Q UPVC SECTION WITH 6mm CLEAR FLOAT GLASS +12mm AIR GAP+6mm REFLECTED GLASS AWING WINDOW | BJ35: 0
BF36: CW12 | BG36: 1700 | BH36: 3240 | BI36: H.Q UPVC SECTION WITH 6mm CLEAR FLOAT GLASS +12mm AIR GAP+6mm REFLECTED GLASS AWING WINDOW | BJ36: 0
B37: Total Area | AH37: =PRODUCT(AH32:AH36) -> 49.41 | AI37: =PRODUCT(AI32:AI36) -> 34.02 | AJ37: =PRODUCT(AJ32:AJ36) -> 22.68 | AK37: =PRODUCT(AK32:AK36) -> 55.08 | AL37: =PRODUCT(AL32:AL36) -> 42.12 | AM37: =PRODUCT(AM32:AM36) -> 49.41 | AN37: =PRODUCT(AN32:AN36) -> 24.3 | AO37: =PRODUCT(AO32:AO36) -> 30.4 | ... BC37: =PRODUCT(BC32:BC36) -> 1.92 | BD37: =SUM(AH37:BC37) -> 370.416 | BE37: m2 | BF37: CW13 | BG37: 1400 | BH37: 3240 | BI37: H.Q UPVC SECTION WITH 6mm CLEAR FLOAT GLASS +12mm AIR GAP+6mm REFLECTED GLASS AWING WINDOW | BJ37: 0
BF38: CW14 | BG38: 2100 | BH38: 3240 | BI38: H.Q UPVC SECTION WITH 6mm CLEAR FLOAT GLASS +12mm AIR GAP+6mm REFLECTED GLASS AWING WINDOW | BJ38: 0
BF39: CW15 | BG39: 800 | BH39: 3240 | BI39: H.Q UPVC SECTION WITH 6mm CLEAR FLOAT GLASS +12mm AIR GAP+6mm REFLECTED GLASS AWING WINDOW | BJ39: 0
B40: FG1 | C40: FG1 | D40: FG1 | E40: FG1 | F40: FG1 | G40: FG1 | H40: FG1 | I40: FG1 | J40: FG1 | K40: FG1 | L40: FG1 | M40: FG1 | N40: FG1 | O40: FG1 | P40: FG1 | Q40: FG1 | R40: FG1 | S40: FG1 | T40: FG1 | U40: FG1 | V40: FG1 | W40: FG1 | X40: FG1 | Y40: FG1 | Z40: FG1 | AA40: FG1 | AB40: FG1 | AC40: FG1 | AD40: FG1 | AE40: FG1 | BF40: CW16 | BG40: 900 | BH40: 3240 | BI40: H.Q UPVC SECTION WITH 6mm CLEAR FLOAT GLASS +12mm AIR GAP+6mm REFLECTED GLASS AWING WINDOW | BJ40: 0
B41: Location | C41: Gf | D41: Gf | E41: Gf | F41: Gf | G41: Gf | H41: Gf | I41: Gf | J41: Gf | K41: Gf | L41: Gf | M41: Gf | N41: Gf | O41: Gf | P41: Gf | Q41: Gf | R41: Gf | S41: Gf | T41: Gf | U41: Gf | V41: Gf | W41: Gf | X41: Gf | Y41: Gf | Z41: Gf | AA41: Gf | AB41: Gf | AC41: Gf | AD41: Gf | AE41: Gf | BF41: CW17 | BG41: 800 | BH41: 3240 | BI41: H.Q UPVC SECTION WITH 6mm CLEAR FLOAT GLASS +12mm AIR GAP+6mm REFLECTED GLASS AWING WINDOW | BJ41: 0
...

Sheet Sheet1
